<?xml version="1.0" ?>

<robot name="logger" xmlns:xacro="https://www.ros.org/wiki/xacro" >
    
  <!-- Constants for robot dimensions -->
  <xacro:property name="PI" value="3.1415926535897931"/>

  <!-- Import all Gazebo-customization elements, including Gazebo colors -->
  <xacro:include filename="$(find loggers_description)/urdf/single_logger.gazebo" />
  <!-- Import Rviz colors -->
  <xacro:include filename="$(find loggers_description)/urdf/materials.xacro" />

  <!-- Used for fixing robot to Gazebo 'base_link' -->
  <!-- <link name="world"/> -->

  <!-- <joint name="joint_world_chassis" type="planar"> -->
  <!--   <parent link="world"/> -->
  <!--   <child link="link_chassis"/> -->
  <!-- </joint> -->

  <link name="link_chassis">
    <visual>
      <origin rpy="0 0 0" xyz="0 0 0"/>
      <geometry>
        <box size="0.4 0.2 0.1"/>
      </geometry>
      <material name="uc_red"/>
    </visual>
    <collision>
      <origin rpy="0 0 0" xyz="0 0 0"/>
      <geometry>
        <box size="0.4 0.2 0.1"/>
      </geometry>
    </collision>
    <inertial>
      <mass value="2"/>
      <origin rpy="0 0 0" xyz="0 0 0"/>
      <inertia ixx="0.0083" ixy="0" ixz="0" iyy="0.0283" iyz="0" izz="0.0333"/>
    </inertial>
  </link>

  <joint name="joint_chassis_caster" type="revolute">
    <parent link="link_chassis"/>
    <child link="link_caster"/>
    <origin rpy="0 0 0" xyz="0.15 0 -0.05"/>
    <limit effort="0" velocity="0" lower="0" upper="0" />
    <axis xyz="0 0 1"/>
  </joint>
        
  <link name="link_caster">
    <visual>
      <origin rpy="0 0 0" xyz="0 0 0"/>
      <geometry>
        <sphere radius="0.04"/>
      </geometry>
      <material name="grey"/>
    </visual>
    <collision>
      <origin rpy=" 0 0 0" xyz="0 0 0"/>
      <geometry>
        <sphere radius="0.04"/>
      </geometry>
      <surface>
        <friction>
          <ode>
            <mu>0</mu>
            <mu2>0</mu2>
            <slip1>1.0</slip1>
            <slip2>1.0</slip2>
          </ode>
        </friction>
      </surface>
    </collision>
    <inertial>
      <mass value="0.02"/>
      <origin rpy="0 0 0" xyz="0 0 0"/>
      <inertia ixx="0.00001" ixy="0" ixz="0" iyy="0.00001" iyz="0" izz="0.00001"/>
    </inertial>
  </link>

  <joint name="joint_chassis_leftwheel" type="continuous">
    <origin rpy="0 0 0" xyz="-0.16 0.12 0.01"/>
    <child link="link_left_wheel" />
    <parent link="link_chassis"/>
    <axis rpy="0 0 0" xyz="0 1 0"/>
  </joint>  

  <link name="link_left_wheel">    
    <visual>
      <origin rpy="${PI/2} 0 0" xyz="0 0 0"/>
      <geometry>
        <cylinder length="0.04" radius="0.1"/>
      </geometry>
      <material name="black"/>
    </visual>
    <collision>
      <origin rpy="${PI/2} 0 0" xyz="0 0 0" />
      <geometry>
        <cylinder length="0.04" radius="0.1"/>
      </geometry>
    </collision>
    <inertial>
      <mass value="0.02"/>
      <origin rpy="0 0 0" xyz="0 0 0"/>
      <inertia ixx="0.0001" ixy="0" ixz="0" iyy="0.0001" iyz="0" izz="0.0001"/>
    </inertial>
  </link>
          
  <joint name="joint_chassis_rightwheel" type="continuous">
    <origin rpy="0 0 0" xyz="-0.16 -0.12 0.01"/>
    <child link="link_right_wheel" />
    <parent link="link_chassis"/>
    <axis rpy="0 0 0" xyz="0 1 0"/>
  </joint>    
    
  <link name="link_right_wheel">    
    <collision>
      <origin rpy="${PI/2} 0 0" xyz="0 0 0" />
      <geometry>
        <cylinder length="0.04" radius="0.1"/>
      </geometry>
    </collision>
    <visual>
      <origin rpy="${PI/2} 0 0" xyz="0 0 0"/>
      <geometry>
        <cylinder length="0.04" radius="0.1"/>
      </geometry>
      <material name="black"/>
    </visual>
    <inertial>
      <mass value="0.01"/>
      <origin rpy="0 0 0" xyz="0 0 0"/>
      <inertia ixx="0.001" ixy="0" ixz="0" iyy="0.001" iyz="0" izz="0.001"/>
    </inertial>
  </link>

  <joint name="joint_chassis_hat" type="revolute">
    <origin rpy="0 0 0" xyz="0.0 0 0.05"/>
    <limit effort="0" lower="0" upper="0" velocity="0"/>
    <child link="link_hat" />
    <parent link="link_chassis"/>
    <axis rpy="0 0 0" xyz="0 0 1"/>
  </joint>    

  <link name="link_hat">
    <visual>
      <origin rpy="0 0 0" xyz="0 0 0.04"/>
      <geometry>
        <cylinder length="0.08" radius="0.02"/>
      </geometry>
      <material name="uc_red"/>
    </visual>
    <collision>
      <origin rpy="0 0 0" xyz="0 0 0.04"/>
      <geometry>
        <cylinder length="0.08" radius="0.02"/>
      </geometry>
    </collision>
    <inertial>
      <mass value="0.01"/>
      <origin rpy="0 0 0" xyz="0 0 0.04"/>
      <inertia ixx="0.00001" ixy="0" ixz="0" iyy="0.00001" iyz="0" izz="0.00001"/>
    </inertial>
  </link>
      
</robot>
